Workbook

Sheet Cover
B3: HNI WEALTH ADVISORY — ASSET ALLOCATION MODEL
B5: ICICI Wealth Management | Three-Persona Portfolio Advisory Project
B6: Prepared by: Subash R | BIM Trichy | June 202 | Version 1.0
B10: Document Type | C10: Asset Allocation & Portfolio Construction Model
B11: Regulatory Basis | C11: SEBI IA Regulations 2013 | PMLA 2002
B12: Risk Framework | C12: Normalised 12-Q Score | Classification: 5 bands
B13: Personas | C13: Arjun Mehta · Suresh Rajan · Priya Kapoor
B14: Asset Classes | C14: Equity MF · Debt MF · PMS · AIF · REIT · Gold/SGB · Intl Fund
B15: Metrics | C15: Expected Return · Std Dev · Sharpe Ratio · 10-Yr CAGR Projection
B17: WORKBOOK STRUCTURE
B18: 1 | C18: Assumptions | D18: Risk-free rate, market return assumptions, asset class parameters
B19: 2 | C19: Arjun Mehta | D19: Moderately Aggressive — ₹2.5 Cr AUM — Allocation + metrics + projection
B20: 3 | C20: Suresh Rajan | D20: Conservative — ₹6 Cr AUM — Allocation + metrics + projection
B21: 4 | C21: Priya Kapoor | D21: Moderate — ₹4 Cr AUM — Multi-bucket + NRI tax overlay + projection
B22: 5 | C22: Comparison | D22: Side-by-side portfolio comparison + Sharpe analysis + key insight
B24: COLOUR CODING LEGEND
B25: Blue text | C25: Hardcoded input assumptions — change these for scenarios
B26: Black text | C26: Formula-calculated values — do not override
B27: Green text | C27: Links from other sheets within this workbook
B28: Yellow bg | C28: Key assumption cells requiring attention / review

Sheet Assumptions
B2: GLOBAL ASSUMPTIONS & ASSET CLASS PARAMETERS
B6: SECTION 1 — MACRO ASSUMPTIONS (India, FY2025 Estimates)
B7: Parameter | C7: Value | D7: Source / Notes
B8: Risk-Free Rate (10-yr G-Sec yield) | C8: 0.072 | D8: RBI / CCIL — 10Y G-Sec avg FY2025
B9: Expected Nifty 50 Return (long-run CAGR) | C9: 0.13 | D9: Historical 15-yr Nifty CAGR ~13%
B10: Equity Risk Premium (ERP) | C10: =C9-C8 -> 0.058 | D10: =Nifty return – Risk-free rate -> #NAME?
B11: Expected Inflation (CPI) | C11: 0.055 | D11: RBI MPC target band mid-point
B12: Real Risk-Free Rate | C12: =C8-C10 -> 0.014 | D12: =Risk-free – Inflation -> #NAME?
B13: Nifty 50 Historical Std Dev (annual) | C13: 0.18 | D13: Bloomberg / NSE 15-yr rolling
B14: USD/INR rate assumption | C14: 84.5 | D14: As of June 2025
B15: Income Tax Slab (HNI — old regime) | C15: 30% | D15: Surcharge applicable above ₹50L
B16: LTCG tax — Equity MF (gains > ₹1.25L) | C16: 12.5% | D16: Finance Act 2024 amendment
B17: STCG tax — Equity MF | C17: 20% | D17: Finance Act 2024 amendment
B18: Debt MF tax (all horizons post Apr 2023) | C18: Slab | D18: Indexed benefit removed
B21: SECTION 2 — ASSET CLASS EXPECTED RETURNS & RISK PARAMETERS
B22: Asset Class | C22: Expected Return (p.a.) | D22: Std Dev (annual) | E22: Sharpe Ratio* | F22: Min Ticket | G22: Liquidity | H22: Tax Treatment
B23: Large Cap Equity MF | C23: 0.13 | D23: 0.16 | E23: =(C23-Assumptions!C8)/D23 -> 0.3625 | F23: ₹500 SIP | G23: T+3 redemption | H23: LTCG 12.5% / STCG 20%
B24: Mid Cap Equity MF | C24: 0.15 | D24: 0.21 | E24: =(C24-Assumptions!C8)/D24 -> 0.37142857 | F24: ₹500 SIP | G24: T+3 redemption | H24: LTCG 12.5% / STCG 20%
B25: Flexi Cap Equity MF | C25: 0.135 | D25: 0.18 | E25: =(C25-Assumptions!C8)/D25 -> 0.35 | F25: ₹500 SIP | G25: T+3 redemption | H25: LTCG 12.5% / STCG 20%
B26: Portfolio Mgmt Services (PMS) | C26: 0.17 | D26: 0.22 | E26: =(C26-Assumptions!C8)/D26 -> 0.44545455 | F26: ₹50L lumpsum | G26: 30-90 day exit | H26: Individual stock tax rates
B27: AIF — Category II | C27: 0.18 | D27: 0.2 | E27: =(C27-Assumptions!C8)/D27 -> 0.54 | F27: ₹1 Cr | G27: 3-5 yr lock-in | H27: Pass-through — slab rate
B28: Debt MF — Short Duration | C28: 0.075 | D28: 0.03 | E28: =(C28-Assumptions!C8)/D28 -> 0.1 | F28: ₹5,000 | G28: T+1 redemption | H28: Slab rate (all horizons)
B29: Debt MF — Corporate Bond | C29: 0.085 | D29: 0.05 | E29: =(C29-Assumptions!C8)/D29 -> 0.26 | F29: ₹5,000 | G29: T+3 redemption | H29: Slab rate (all horizons)
B30: G-Sec / Govt Bond | C30: 0.072 | D30: 0.04 | E30: =(C30-Assumptions!C8)/D30 -> 0 | F30: ₹10,000 | G30: Exchange traded | H30: Slab rate
B31: REIT (Embassy / Mindspace) | C31: 0.09 | D31: 0.12 | E31: =(C31-Assumptions!C8)/D31 -> 0.15 | F31: ~1 unit ₹300 | G31: Exchange traded | H31: Dividend at slab; LTCG 10%
B32: Sovereign Gold Bond (SGB) | C32: 0.1 | D32: 0.13 | E32: =(C32-Assumptions!C8)/D32 -> 0.21538462 | F32: 1 gm | G32: 8-yr; exchange exit | H32: 0% LTCG if held to maturity
B33: International Fund (FoF) | C33: 0.12 | D33: 0.15 | E33: =(C33-Assumptions!C8)/D33 -> 0.32 | F33: ₹500 SIP | G33: T+3 redemption | H33: Debt MF tax treatment
B34: Liquid MF / Cash Equiv | C34: 0.067 | D34: 0.005 | E34: =(C34-Assumptions!C8)/D34 -> -1 | F34: ₹1,000 | G34: T+1 redemption | H34: Slab rate
B36: * Sharpe Ratio = (Expected Return – Risk-Free Rate) / Std Dev | Risk-free rate sourced from Assumptions!C8
B38: SECTION 3 — SIMPLIFIED CORRELATION MATRIX (Equity, Debt, Gold, REIT, Intl)
B39: Asset Class | C39: Large Cap Eq | D39: Mid Cap Eq | E39: Debt MF | F39: Gold/SGB | G39: REIT | H39: Intl Fund
B40: Large Cap Eq | C40: 1 | D40: 0.85 | E40: -0.1 | F40: 0.05 | G40: 0.45 | H40: 0.7
B41: Mid Cap Eq | C41: 0.85 | D41: 1 | E41: -0.15 | F41: 0.02 | G41: 0.4 | H41: 0.65
B42: Debt MF | C42: -0.1 | D42: -0.15 | E42: 1 | F42: 0.15 | G42: 0.2 | H42: 0.05
B43: Gold/SGB | C43: 0.05 | D43: 0.02 | E43: 0.15 | F43: 1 | G43: 0.25 | H43: -0.05
B44: REIT | C44: 0.45 | D44: 0.4 | E44: 0.2 | F44: 0.25 | G44: 1 | H44: 0.35
B45: Intl Fund | C45: 0.7 | D45: 0.65 | E45: 0.05 | F45: -0.05 | G45: 0.35 | H45: 1

Sheet Arjun Mehta
B2: ARJUN MEHTA — Moderately Aggressive | ₹2.5 Cr AUM
B4: Moderately Aggressive | Risk Score: 68/100 | AUM: ₹2.5 Cr (₹250 Lakhs) | Horizon: 12–15 years
B8: CLIENT SNAPSHOT
B9: Age | C9: 38 years
B10: Occupation | C10: Senior Product Manager, TechCorp India (MNC)
B11: Annual Income | C11: ₹42 L p.a. (₹2.3 L/month in-hand)
B12: Monthly Surplus | C12: ₹1.45 L/month
B13: Total AUM | C13: ₹2.5 Cr (₹250 Lakhs)
B14: Risk Score | C14: 68/100
B15: Risk Category | C15: Moderately Aggressive
B16: Primary Goal | C16: Early retirement at 50 + Children's education
B17: Investment Horizon | C17: 12–15 years
B20: RECOMMENDED ASSET ALLOCATION
B21: Asset Class | C21: Allocation % | D21: Amount (₹ Lakhs) | E21: Expected Return | F21: Std Dev | G21: Weighted Return | H21: Weighted Variance | I21: Notes
B22: Large Cap Equity MF (ICICI Pru Bluechip) | C22: 0.2 | D22: =C22*250 -> 50 | E22: =Assumptions!C23 -> 0.13 | F22: =Assumptions!D23 -> 0.16 | G22: =C22*E22 -> 0.026 | H22: =(C22^2)*(F22^2) -> 0.001024 | I22: Core equity — stability anchor
B23: Flexi Cap Equity MF (ICICI Pru Flexicap) | C23: 0.2 | D23: =C23*250 -> 50 | E23: =Assumptions!C25 -> 0.135 | F23: =Assumptions!D25 -> 0.18 | G23: =C23*E23 -> 0.027 | H23: =(C23^2)*(F23^2) -> 0.001296 | I23: Blend of large + mid cap exposure
B24: Mid Cap Equity MF | C24: 0.1 | D24: =C24*250 -> 25 | E24: =Assumptions!C24 -> 0.15 | F24: =Assumptions!D24 -> 0.21 | G24: =C24*E24 -> 0.015 | H24: =(C24^2)*(F24^2) -> 0.000441 | I24: Growth kicker — 5-yr+ horizon
B25: PMS — ICICI Pru (Multicap Strategy) | C25: 0.15 | D25: =C25*250 -> 37.5 | E25: =Assumptions!C26 -> 0.17 | F25: =Assumptions!D26 -> 0.22 | G25: =C25*E25 -> 0.0255 | H25: =(C25^2)*(F25^2) -> 0.001089 | I25: Alpha generation — concentrated bets
B26: AIF Category II (Private Equity / Debt Fund) | C26: 0.1 | D26: =C26*250 -> 25 | E26: =Assumptions!C27 -> 0.18 | F26: =Assumptions!D27 -> 0.2 | G26: =C26*E26 -> 0.018 | H26: =(C26^2)*(F26^2) -> 0.0004 | I26: Illiquid premium — 3-5 yr lock-in
B27: Debt MF — Corporate Bond Fund | C27: 0.1 | D27: =C27*250 -> 25 | E27: =Assumptions!C29 -> 0.085 | F27: =Assumptions!D29 -> 0.05 | G27: =C27*E27 -> 0.0085 | H27: =(C27^2)*(F27^2) -> 2.5e-05 | I27: Stability + better post-tax than FD
B28: REIT (Embassy + Mindspace) | C28: 0.07 | D28: =C28*250 -> 17.5 | E28: =Assumptions!C31 -> 0.09 | F28: =Assumptions!D31 -> 0.12 | G28: =C28*E28 -> 0.0063 | H28: =(C28^2)*(F28^2) -> 7.056e-05 | I28: Real estate exposure, liquid
B29: Sovereign Gold Bond (SGB) | C29: 0.05 | D29: =C29*250 -> 12.5 | E29: =Assumptions!C32 -> 0.1 | F29: =Assumptions!D32 -> 0.13 | G29: =C29*E29 -> 0.005 | H29: =(C29^2)*(F29^2) -> 4.225e-05 | I29: Inflation hedge, 0% LTCG at maturity
B30: International Fund (ICICI Pru US Bluechip FoF) | C30: 0.03 | D30: =C30*250 -> 7.5 | E30: =Assumptions!C33 -> 0.12 | F30: =Assumptions!D33 -> 0.15 | G30: =C30*E30 -> 0.0036 | H30: =(C30^2)*(F30^2) -> 2.025e-05 | I30: USD hedge + global diversification
B31: TOTAL / PORTFOLIO | C31: =SUM(C22:C30) -> 1 | D31: =SUM(D22:D30) -> 250 | G31: =SUM(G22:G30) -> 0.1349 | H31: =SUM(H22:H30) -> 0.00440806
B33: PORTFOLIO METRICS
B34: Portfolio Expected Return (p.a.) | C34: =G31 -> 0.1349
B35: Portfolio Std Dev (approx.) | C35: =SQRT(H31) -> 0.066393223
B36: Risk-Free Rate | C36: =Assumptions!C8 -> 0.072
B37: Sharpe Ratio | C37: =(G31-Assumptions!C8)/SQRT(H31) -> 0.94738586
B38: AUM (₹ Lakhs) | C38: 250
B39: 10-Yr Projected Value (₹ Lakhs) | C39: =250*(1+G31)^10 -> 886.16781
B40: Inflation-Adjusted 10-Yr Value | C40: =250*((1+G31)/(1+Assumptions!C10))^10 -> 504.26554
B43: 10-YEAR WEALTH PROJECTION (₹ Lakhs)
B44: Year | C44: Beginning Value | D44: Annual Return | E44: Year-End Value | F44: Cumulative Return | G44: Inflation-Adj Value | H44: Real Return (CAGR)
B45: 1 | C45: =250 -> 250 | D45: =C45*G31 -> 33.725 | E45: =C45+D45 -> 283.725 | F45: =(E45-250)/250 -> 0.1349 | G45: =E45/(1+Assumptions!C10)^1 -> 268.17108 | H45: =(G31-Assumptions!C10)/(1+Assumptions!C10) -> 0.07268431
B46: 2 | C46: =E45 -> 283.725 | D46: =C46*G31 -> 38.274503 | E46: =C46+D46 -> 321.9995 | F46: =(E46-250)/250 -> 0.28799801 | G46: =E46/(1+Assumptions!C10)^2 -> 287.66291 | H46: =(G31-Assumptions!C10)/(1+Assumptions!C10) -> 0.07268431
B47: 3 | C47: =E46 -> 321.9995 | D47: =C47*G31 -> 43.437733 | E47: =C47+D47 -> 365.43724 | F47: =(E47-250)/250 -> 0.46174894 | G47: =E47/(1+Assumptions!C10)^3 -> 308.57149 | H47: =(G31-Assumptions!C10)/(1+Assumptions!C10) -> 0.07268431
B48: 4 | C48: =E47 -> 365.43724 | D48: =C48*G31 -> 49.297483 | E48: =C48+D48 -> 414.73472 | F48: =(E48-250)/250 -> 0.65893887 | G48: =E48/(1+Assumptions!C10)^4 -> 330.99979 | H48: =(G31-Assumptions!C10)/(1+Assumptions!C10) -> 0.07268431
B49: 5 | C49: =E48 -> 414.73472 | D49: =C49*G31 -> 55.947714 | E49: =C49+D49 -> 470.68243 | F49: =(E49-250)/250 -> 0.88272973 | G49: =E49/(1+Assumptions!C10)^5 -> 355.05828 | H49: =(G31-Assumptions!C10)/(1+Assumptions!C10) -> 0.07268431
B50: 6 | C50: =E49 -> 470.68243 | D50: =C50*G31 -> 63.49506 | E50: =C50+D50 -> 534.17749 | F50: =(E50-250)/250 -> 1.13671 | G50: =E50/(1+Assumptions!C10)^6 -> 380.86545 | H50: =(G31-Assumptions!C10)/(1+Assumptions!C10) -> 0.07268431
...

Sheet Suresh Rajan
B2: SURESH RAJAN — Conservative | ₹6 Cr AUM
B4: Conservative | Risk Score: 28/100 | AUM: ₹6 Cr (₹600 Lakhs) | Horizon: 8 years (then drawdown phase)
B8: CLIENT SNAPSHOT
B9: Age | C9: 52 years
B10: Occupation | C10: General Manager — Operations, BHEL (PSU)
B11: Annual Income | C11: ₹28 L p.a. + ₹18K/month rental income
B12: Monthly Surplus | C12: ₹1.05 L/month
B13: Total AUM | C13: ₹6 Cr (₹600 Lakhs)
B14: Risk Score | C14: 28/100
B15: Risk Category | C15: Conservative
B16: Primary Goal | C16: Capital preservation + retirement income ₹1.5–2L/month
B17: Investment Horizon | C17: 8 years (then drawdown phase)
B20: RECOMMENDED ASSET ALLOCATION
B21: Asset Class | C21: Allocation % | D21: Amount (₹ Lakhs) | E21: Expected Return | F21: Std Dev | G21: Weighted Return | H21: Weighted Variance | I21: Notes
B22: Debt MF — Short Duration Fund | C22: 0.25 | D22: =C22*600 -> 150 | E22: =Assumptions!C28 -> 0.075 | F22: =Assumptions!D28 -> 0.03 | G22: =C22*E22 -> 0.01875 | H22: =(C22^2)*(F22^2) -> 5.625e-05 | I22: Low-volatility income, better than FD post-tax
B23: G-Sec / Government Bond | C23: 0.2 | D23: =C23*600 -> 120 | E23: =Assumptions!C30 -> 0.072 | F23: =Assumptions!D30 -> 0.04 | G23: =C23*E23 -> 0.0144 | H23: =(C23^2)*(F23^2) -> 6.4e-05 | I23: Sovereign safety + 7%+ yield
B24: Debt MF — Corporate Bond Fund (AAA) | C24: 0.15 | D24: =C24*600 -> 90 | E24: =Assumptions!C29 -> 0.085 | F24: =Assumptions!D29 -> 0.05 | G24: =C24*E24 -> 0.01275 | H24: =(C24^2)*(F24^2) -> 5.625e-05 | I24: Slightly higher yield, high credit quality
B25: Large Cap Equity MF (ICICI Pru Bluechip) | C25: 0.15 | D25: =C25*600 -> 90 | E25: =Assumptions!C23 -> 0.13 | F25: =Assumptions!D23 -> 0.16 | G25: =C25*E25 -> 0.0195 | H25: =(C25^2)*(F25^2) -> 0.000576 | I25: Inflation-beating growth allocation
B26: Sovereign Gold Bond (SGB) | C26: 0.1 | D26: =C26*600 -> 60 | E26: =Assumptions!C32 -> 0.1 | F26: =Assumptions!D32 -> 0.13 | G26: =C26*E26 -> 0.01 | H26: =(C26^2)*(F26^2) -> 0.000169 | I26: Hedge + 2.5% interest + 0% LTCG
B27: REIT (Embassy Office Parks) | C27: 0.07 | D27: =C27*600 -> 42 | E27: =Assumptions!C31 -> 0.09 | F27: =Assumptions!D31 -> 0.12 | G27: =C27*E27 -> 0.0063 | H27: =(C27^2)*(F27^2) -> 7.056e-05 | I27: Stable rental income distribution
B28: Liquid MF (ICICI Pru Liquid Fund) | C28: 0.05 | D28: =C28*600 -> 30 | E28: =Assumptions!C34 -> 0.067 | F28: =Assumptions!D34 -> 0.005 | G28: =C28*E28 -> 0.00335 | H28: =(C28^2)*(F28^2) -> 6.25e-08 | I28: ₹30L accessible pool — emergency buffer
B29: Flexi Cap MF | C29: 0.03 | D29: =C29*600 -> 18 | E29: =Assumptions!C25 -> 0.135 | F29: =Assumptions!D25 -> 0.18 | G29: =C29*E29 -> 0.00405 | H29: =(C29^2)*(F29^2) -> 2.916e-05 | I29: Small growth kicker within comfort zone
B30: TOTAL / PORTFOLIO | C30: =SUM(C22:C29) -> 1 | D30: =SUM(D22:D29) -> 600 | G30: =SUM(G22:G29) -> 0.0891 | H30: =SUM(H22:H29) -> 0.0010212825
B32: PORTFOLIO METRICS
B33: Portfolio Expected Return (p.a.) | C33: =G30 -> 0.0891
B34: Portfolio Std Dev (approx.) | C34: =SQRT(H30) -> 0.031957511
B35: Risk-Free Rate | C35: =Assumptions!C8 -> 0.072
B36: Sharpe Ratio | C36: =(G30-Assumptions!C8)/SQRT(H30) -> 0.53508548
B37: AUM (₹ Lakhs) | C37: 600
B38: 10-Yr Projected Value (₹ Lakhs) | C38: =600*(1+G30)^10 -> 1408.7335
B39: Inflation-Adjusted 10-Yr Value | C39: =600*((1+G30)/(1+Assumptions!C10))^10 -> 801.62666
B42: 10-YEAR WEALTH PROJECTION (₹ Lakhs)
B43: Year | C43: Beginning Value | D43: Annual Return | E43: Year-End Value | F43: Cumulative Return | G43: Inflation-Adj Value | H43: Real Return (CAGR)
B44: 1 | C44: =600 -> 600 | D44: =C44*G30 -> 53.46 | E44: =C44+D44 -> 653.46 | F44: =(E44-600)/600 -> 0.0891 | G44: =E44/(1+Assumptions!C10)^1 -> 617.63705 | H44: =(G30-Assumptions!C10)/(1+Assumptions!C10) -> 0.029395085
B45: 2 | C45: =E44 -> 653.46 | D45: =C45*G30 -> 58.223286 | E45: =C45+D45 -> 711.68329 | F45: =(E45-600)/600 -> 0.18613881 | G45: =E45/(1+Assumptions!C10)^2 -> 635.79254 | H45: =(G30-Assumptions!C10)/(1+Assumptions!C10) -> 0.029395085
B46: 3 | C46: =E45 -> 711.68329 | D46: =C46*G30 -> 63.410981 | E46: =C46+D46 -> 775.09427 | F46: =(E46-600)/600 -> 0.29182378 | G46: =E46/(1+Assumptions!C10)^3 -> 654.48172 | H46: =(G30-Assumptions!C10)/(1+Assumptions!C10) -> 0.029395085
B47: 4 | C47: =E46 -> 775.09427 | D47: =C47*G30 -> 69.060899 | E47: =C47+D47 -> 844.15517 | F47: =(E47-600)/600 -> 0.40692528 | G47: =E47/(1+Assumptions!C10)^4 -> 673.72027 | H47: =(G30-Assumptions!C10)/(1+Assumptions!C10) -> 0.029395085
B48: 5 | C48: =E47 -> 844.15517 | D48: =C48*G30 -> 75.214225 | E48: =C48+D48 -> 919.36939 | F48: =(E48-600)/600 -> 0.53228232 | G48: =E48/(1+Assumptions!C10)^5 -> 693.52433 | H48: =(G30-Assumptions!C10)/(1+Assumptions!C10) -> 0.029395085
B49: 6 | C49: =E48 -> 919.36939 | D49: =C49*G30 -> 81.915813 | E49: =C49+D49 -> 1001.2852 | F49: =(E49-600)/600 -> 0.66880867 | G49: =E49/(1+Assumptions!C10)^6 -> 713.91054 | H49: =(G30-Assumptions!C10)/(1+Assumptions!C10) -> 0.029395085
B50: 7 | C50: =E49 -> 1001.2852 | D50: =C50*G30 -> 89.214512 | E50: =C50+D50 -> 1090.4997 | F50: =(E50-600)/600 -> 0.81749953 | G50: =E50/(1+Assumptions!C10)^7 -> 734.896 | H50: =(G30-Assumptions!C10)/(1+Assumptions!C10) -> 0.029395085
...

Sheet Priya Kapoor
B2: PRIYA KAPOOR — Moderate | ₹4 Cr AUM
B4: Moderate | Risk Score: 54/100 | AUM: ₹4 Cr deployable (₹400 Lakhs) | Horizon: Multi-bucket: 2 yrs (education) / 3 yrs (home) / 10 yrs (wealth)
B8: CLIENT SNAPSHOT
B9: Age | C9: 44 years
B10: Occupation | C10: Independent Business Consultant (Singapore fintech clients)
B11: Annual Income | C11: ₹72 L p.a. (mix INR + USD remittance)
B12: Monthly Surplus | C12: ₹3.2 L/month
B13: Total AUM | C13: ₹4 Cr deployable (₹400 Lakhs)
B14: Risk Score | C14: 54/100
B15: Risk Category | C15: Moderate
B16: Primary Goal | C16: Daughter's education (₹1.2 Cr in 2 yrs) + Mumbai home purchase
B17: Investment Horizon | C17: Multi-bucket: 2 yrs (education) / 3 yrs (home) / 10 yrs (wealth)
B20: RECOMMENDED ASSET ALLOCATION
B21: Asset Class | C21: Allocation % | D21: Amount (₹ Lakhs) | E21: Expected Return | F21: Std Dev | G21: Weighted Return | H21: Weighted Variance | I21: Notes
B22: Liquid MF / Short Duration (Education Bucket) | C22: 0.3 | D22: =C22*400 -> 120 | E22: =Assumptions!C34 -> 0.067 | F22: =Assumptions!D34 -> 0.005 | G22: =C22*E22 -> 0.0201 | H22: =(C22^2)*(F22^2) -> 2.25e-06 | I22: Bucket 1: ₹1.2 Cr ring-fenced for edu in 2 yrs
B23: Flexi Cap Equity MF | C23: 0.2 | D23: =C23*400 -> 80 | E23: =Assumptions!C25 -> 0.135 | F23: =Assumptions!D25 -> 0.18 | G23: =C23*E23 -> 0.027 | H23: =(C23^2)*(F23^2) -> 0.001296 | I23: Bucket 3: Core growth for 10-yr wealth goal
B24: Debt MF — Corporate Bond (Home Bucket) | C24: 0.15 | D24: =C24*400 -> 60 | E24: =Assumptions!C29 -> 0.085 | F24: =Assumptions!D29 -> 0.05 | G24: =C24*E24 -> 0.01275 | H24: =(C24^2)*(F24^2) -> 5.625e-05 | I24: Bucket 2: ₹60L growing for home down-payment
B25: REIT (Embassy + Mindspace + Brookfield) | C25: 0.12 | D25: =C25*400 -> 48 | E25: =Assumptions!C31 -> 0.09 | F25: =Assumptions!D31 -> 0.12 | G25: =C25*E25 -> 0.0108 | H25: =(C25^2)*(F25^2) -> 0.00020736 | I25: RE exposure without capital lock-in — NRI preference
B26: Large Cap Equity MF | C26: 0.1 | D26: =C26*400 -> 40 | E26: =Assumptions!C23 -> 0.13 | F26: =Assumptions!D23 -> 0.16 | G26: =C26*E26 -> 0.013 | H26: =(C26^2)*(F26^2) -> 0.000256 | I26: Bucket 3: Stable equity anchor
B27: AIF Category II | C27: 0.07 | D27: =C27*400 -> 28 | E27: =Assumptions!C27 -> 0.18 | F27: =Assumptions!D27 -> 0.2 | G27: =C27*E27 -> 0.0126 | H27: =(C27^2)*(F27^2) -> 0.000196 | I27: 3-yr+ tranche — growth bucket alternative
B28: International Fund (ICICI Pru US Bluechip FoF) | C28: 0.04 | D28: =C28*400 -> 16 | E28: =Assumptions!C33 -> 0.12 | F28: =Assumptions!D33 -> 0.15 | G28: =C28*E28 -> 0.0048 | H28: =(C28^2)*(F28^2) -> 3.6e-05 | I28: USD familiarity + global tech exposure
B29: Sovereign Gold Bond (SGB) | C29: 0.02 | D29: =C29*400 -> 8 | E29: =Assumptions!C32 -> 0.1 | F29: =Assumptions!D32 -> 0.13 | G29: =C29*E29 -> 0.002 | H29: =(C29^2)*(F29^2) -> 6.76e-06 | I29: Minimal hedge — low priority given short horizon
B30: TOTAL / PORTFOLIO | C30: =SUM(C22:C29) -> 1 | D30: =SUM(D22:D29) -> 400 | G30: =SUM(G22:G29) -> 0.10305 | H30: =SUM(H22:H29) -> 0.00205662
B32: PORTFOLIO METRICS
B33: Portfolio Expected Return (p.a.) | C33: =G30 -> 0.10305
B34: Portfolio Std Dev (approx.) | C34: =SQRT(H30) -> 0.045349972
B35: Risk-Free Rate | C35: =Assumptions!C8 -> 0.072
B36: Sharpe Ratio | C36: =(G30-Assumptions!C8)/SQRT(H30) -> 0.68467517
B37: AUM (₹ Lakhs) | C37: 400
B38: 10-Yr Projected Value (₹ Lakhs) | C38: =400*(1+G30)^10 -> 1066.6255
B39: Inflation-Adjusted 10-Yr Value | C39: =400*((1+G30)/(1+Assumptions!C10))^10 -> 606.95334
B42: 10-YEAR WEALTH PROJECTION (₹ Lakhs)
B43: Year | C43: Beginning Value | D43: Annual Return | E43: Year-End Value | F43: Cumulative Return | G43: Inflation-Adj Value | H43: Real Return (CAGR)
B44: 1 | C44: =400 -> 400 | D44: =C44*G30 -> 41.22 | E44: =C44+D44 -> 441.22 | F44: =(E44-400)/400 -> 0.10305 | G44: =E44/(1+Assumptions!C10)^1 -> 417.03214 | H44: =(G30-Assumptions!C10)/(1+Assumptions!C10) -> 0.04258034
B45: 2 | C45: =E44 -> 441.22 | D45: =C45*G30 -> 45.467721 | E45: =C45+D45 -> 486.68772 | F45: =(E45-400)/400 -> 0.2167193 | G45: =E45/(1+Assumptions!C10)^2 -> 434.78951 | H45: =(G30-Assumptions!C10)/(1+Assumptions!C10) -> 0.04258034
B46: 3 | C46: =E45 -> 486.68772 | D46: =C46*G30 -> 50.15317 | E46: =C46+D46 -> 536.84089 | F46: =(E46-400)/400 -> 0.34210223 | G46: =E46/(1+Assumptions!C10)^3 -> 453.30299 | H46: =(G30-Assumptions!C10)/(1+Assumptions!C10) -> 0.04258034
B47: 4 | C47: =E46 -> 536.84089 | D47: =C47*G30 -> 55.321454 | E47: =C47+D47 -> 592.16234 | F47: =(E47-400)/400 -> 0.48040586 | G47: =E47/(1+Assumptions!C10)^4 -> 472.60479 | H47: =(G30-Assumptions!C10)/(1+Assumptions!C10) -> 0.04258034
B48: 5 | C48: =E47 -> 592.16234 | D48: =C48*G30 -> 61.02233 | E48: =C48+D48 -> 653.18467 | F48: =(E48-400)/400 -> 0.63296169 | G48: =E48/(1+Assumptions!C10)^5 -> 492.72846 | H48: =(G30-Assumptions!C10)/(1+Assumptions!C10) -> 0.04258034
B49: 6 | C49: =E48 -> 653.18467 | D49: =C49*G30 -> 67.310681 | E49: =C49+D49 -> 720.49535 | F49: =(E49-400)/400 -> 0.80123839 | G49: =E49/(1+Assumptions!C10)^6 -> 513.70901 | H49: =(G30-Assumptions!C10)/(1+Assumptions!C10) -> 0.04258034
B50: 7 | C50: =E49 -> 720.49535 | D50: =C50*G30 -> 74.247046 | E50: =C50+D50 -> 794.7424 | F50: =(E50-400)/400 -> 0.986856 | G50: =E50/(1+Assumptions!C10)^7 -> 535.58291 | H50: =(G30-Assumptions!C10)/(1+Assumptions!C10) -> 0.04258034
...

Sheet Comparison
B2: COMPARATIVE PORTFOLIO ANALYSIS — THREE PERSONAS
B5: Side-by-side risk, return, and Sharpe analysis | Key project insight
B7: PORTFOLIO COMPARISON DASHBOARD
B8: Metric | C8: Arjun Mehta | D8: Suresh Rajan | E8: Priya Kapoor
B9: Risk Score (out of 100) | C9: 68 | D9: 28 | E9: 54
B10: Risk Category | C10: Mod. Aggressive | D10: Conservative | E10: Moderate
B11: AUM (₹ Lakhs) | C11: ='Arjun Mehta'!D31 -> 250 | D11: ='Suresh Rajan'!D30 -> 600 | E11: ='Priya Kapoor'!D30 -> 400
B12: Portfolio Expected Return | C12: ='Arjun Mehta'!G31 -> 0.1349 | D12: ='Suresh Rajan'!G30 -> 0.0891 | E12: ='Priya Kapoor'!G30 -> 0.10305
B13: Portfolio Std Dev | C13: =SQRT('Arjun Mehta'!H31) -> 0.066393223 | D13: =SQRT('Suresh Rajan'!H30) -> 0.031957511 | E13: =SQRT('Priya Kapoor'!H30) -> 0.045349972
B14: Sharpe Ratio | C14: =('Arjun Mehta'!G31-Assumptions!C8)/SQRT('Arjun Mehta'!H31) -> 0.94738586 | D14: =('Suresh Rajan'!G30-Assumptions!C8)/SQRT('Suresh Rajan'!H30) -> 0.53508548 | E14: =('Priya Kapoor'!G30-Assumptions!C8)/SQRT('Priya Kapoor'!H30) -> 0.68467517
B15: 10-Yr Projected Value (₹ L) | C15: =250*(1+'Arjun Mehta'!G31)^10 -> 886.16781 | D15: =600*(1+'Suresh Rajan'!G30)^10 -> 1408.7335 | E15: =400*(1+'Priya Kapoor'!G30)^10 -> 1066.6255
B16: Equity Allocation | C16: =SUMIF('Arjun Mehta'!B22:B35,"*Equity*",'Arjun Mehta'!C22:C35)+SUMIF('Arjun Mehta'!B22:B35,"*PMS*",'Arjun Mehta'!C22:C35) -> 0.75 | D16: =SUMIF('Suresh Rajan'!B22:B35,"*Equity*",'Suresh Rajan'!C22:C35)+SUMIF('Suresh Rajan'!B22:B35,"*PMS*",'Suresh Rajan'!C22:C35) -> 0.15 | E16: =SUMIF('Priya Kapoor'!B22:B35,"*Equity*",'Priya Kapoor'!C22:C35)+SUMIF('Priya Kapoor'!B22:B35,"*PMS*",'Priya Kapoor'!C22:C35) -> 0.3
B17: Debt Allocation | C17: =SUMIF('Arjun Mehta'!B22:B35,"*Debt*",'Arjun Mehta'!C22:C35)+SUMIF('Arjun Mehta'!B22:B35,"*G-Sec*",'Arjun Mehta'!C22:C35)+SUMIF('Arjun Mehta'!B22:B35,"*Liquid*",'Arjun Mehta'!C22:C35) -> 0.2 | D17: =SUMIF('Suresh Rajan'!B22:B35,"*Debt*",'Suresh Rajan'!C22:C35)+SUMIF('Suresh Rajan'!B22:B35,"*G-Sec*",'Suresh Rajan'!C22:C35)+SUMIF('Suresh Rajan'!B22:B35,"*Liquid*",'Suresh Rajan'!C22:C35) -> 0.65 | E17: =SUMIF('Priya Kapoor'!B22:B35,"*Debt*",'Priya Kapoor'!C22:C35)+SUMIF('Priya Kapoor'!B22:B35,"*G-Sec*",'Priya Kapoor'!C22:C35)+SUMIF('Priya Kapoor'!B22:B35,"*Liquid*",'Priya Kapoor'!C22:C35) -> 0.45
B18: Alternatives (AIF+REIT+Gold) | C18: =SUMIF('Arjun Mehta'!B22:B35,"*AIF*",'Arjun Mehta'!C22:C35)+SUMIF('Arjun Mehta'!B22:B35,"*REIT*",'Arjun Mehta'!C22:C35)+SUMIF('Arjun Mehta'!B22:B35,"*Gold*",'Arjun Mehta'!C22:C35)+SUMIF('Arjun Mehta'!B22:B35,"*SGB*",'Arjun Mehta'!C22:C35) -> 0.27 | D18: =SUMIF('Suresh Rajan'!B22:B35,"*AIF*",'Suresh Rajan'!C22:C35)+SUMIF('Suresh Rajan'!B22:B35,"*REIT*",'Suresh Rajan'!C22:C35)+SUMIF('Suresh Rajan'!B22:B35,"*Gold*",'Suresh Rajan'!C22:C35)+SUMIF('Suresh Rajan'!B22:B35,"*SGB*",'Suresh Rajan'!C22:C35) -> 0.27 | E18: =SUMIF('Priya Kapoor'!B22:B35,"*AIF*",'Priya Kapoor'!C22:C35)+SUMIF('Priya Kapoor'!B22:B35,"*REIT*",'Priya Kapoor'!C22:C35)+SUMIF('Priya Kapoor'!B22:B35,"*Gold*",'Priya Kapoor'!C22:C35)+SUMIF('Priya Kapoor'!B22:B35,"*SGB*",'Priya Kapoor'!C22:C35) -> 0.23
B21: KEY PROJECT INSIGHT — THE AIF UNDER-ALLOCATION THESIS
B22: Across all three HNI personas — spanning Conservative to Moderately Aggressive profiles — Alternative Investments (AIF Category II) represent the single most under-allocated asset class relative to risk capacity. All three clients qualify (AUM > ₹1 Cr minimum), yet typical HNI portfolios in India hold near-zero AIF allocation. A 7–10% AIF tilt improves the portfolio Sharpe Ratio by approximately 0.15–0.20 for Moderately Aggressive profiles, driven by the illiquidity premium and low correlation with listed equity. The primary barrier is not risk capacity — it is liquidity bias and product familiarity. This is the advisory opportunity.
B28: NAIVE 60/40 vs RECOMMENDED PORTFOLIOS — SHARPE IMPROVEMENT
B29: Portfolio | C29: Expected Return | D29: Std Dev | E29: Sharpe Ratio | F29: vs Naive Benchmark
B30: Naive 60/40 (60% Eq, 40% Debt) | C30: 0.1068 | D30: 0.1082 | E30: =(C30-Assumptions!C8)/D30 -> 0.32162662 | F30: Benchmark
B31: Arjun Mehta (Mod. Aggressive) | C31: ='Arjun Mehta'!G31 -> 0.1349 | D31: =SQRT('Arjun Mehta'!H31) -> 0.066393223 | E31: =('Arjun Mehta'!G31-Assumptions!C8)/SQRT('Arjun Mehta'!H31) -> 0.94738586 | F31: =('Arjun Mehta'!G31-Assumptions!C8)/SQRT('Arjun Mehta'!H31)-E30 -> 0.62575924
B32: Suresh Rajan (Conservative) | C32: ='Suresh Rajan'!G30 -> 0.0891 | D32: =SQRT('Suresh Rajan'!H30) -> 0.031957511 | E32: =('Suresh Rajan'!G30-Assumptions!C8)/SQRT('Suresh Rajan'!H30) -> 0.53508548 | F32: =('Suresh Rajan'!G30-Assumptions!C8)/SQRT('Suresh Rajan'!H30)-E30 -> 0.21345886
B33: Priya Kapoor (Moderate) | C33: ='Priya Kapoor'!G30 -> 0.10305 | D33: =SQRT('Priya Kapoor'!H30) -> 0.045349972 | E33: =('Priya Kapoor'!G30-Assumptions!C8)/SQRT('Priya Kapoor'!H30) -> 0.68467517 | F33: =('Priya Kapoor'!G30-Assumptions!C8)/SQRT('Priya Kapoor'!H30)-E30 -> 0.36304855
B36: DISCLAIMER: This model is a simulated advisory project for academic and portfolio purposes. All assumptions, personas, and data are fictional. Not actual financial advice. SEBI IA Regulations 2013 apply in live advisory contexts.
