Workbook

Sheet 1. Cover & Dashboard
A1: REPCO HOME FINANCE LIMITED - VALUATION MODEL
A2: Integrated Residual Income (Excess Return) Model
A4: Author / Analyst: | B4: Subash R.
A5: Institution / Context: | B5: Bharathidasan Institute of Management (BIM) - PGP Section-A (Roll: 42052)
A6: Purpose: | B6: Academic Panel Presentation & Model Template Formulation
A7: Date / Timestamp: | B7: August 2026
A9: COMPANY OVERVIEW
A10: Company Name: | B10: Repco Home Finance Ltd
A11: Sector: | B11: Housing Finance Company (HFC)
A12: Current Market Price (CMP): | B12: 362
A13: Intrinsic Value per Share: | B13: ='4. Residual Income Valuation'!B28 -> 980.54589
A14: Implied Upside: | B14: ='4. Residual Income Valuation'!B30 -> 1.7086903
A15: Recommendation: | B15: Undervalued under Base-Case assumptions (see Sensitivity, Sheet 5, before treating as a Buy call)
A17: VALUATION RANGE & VALUE CREATION CHECK
A18: Bear Case (Ke 13%, g 3%) Value/Share: | B18: ='5.Sensitivity analysis'!I6 -> 750.13487
A19: Base Case (Ke 11.46%, g 5%) Value/Share: | B19: ='5.Sensitivity analysis'!G8 -> 980.54589
A20: Bull Case (Ke 9%, g 7%) Value/Share: | B20: ='5.Sensitivity analysis'!E10 -> 2579.3022
A21: FY28E ROE vs Cost of Equity (Value Spread): | B21: ='4. Residual Income Valuation'!C36 -> 0.027910124
A22: Note: | B22: Positive spread = ROE exceeds Ke = the company is creating economic value, not merely reporting accounting profit. Full sensitivity grid on Sheet 5.
A24: MODELING GUIDELINES & COLOR CODING
A25: BLUE FONT on YELLOW FILL | B25: Hardcoded Inputs / Assumptions (Changeable)
A26: BLACK FONT on WHITE FILL | B26: Formulas & Calculations (Do not modify manually)
A28: KEY ARCHITECTURAL FIXES (vs Traditional Models)
A29: 1. No FCFE: | B29: HFCs require cash outflows to grow loans. Discounting negative FCFE yields false negative valuations. This model uses Residual Income.
A30: 2. Debt is the Plug: | B30: You cannot hardcode D/E ratios. We project Loans & Equity, and Borrowings solve the balance sheet automatically.
A31: 3. Interest Expense: | B31: Calculated strictly on average Borrowings, NOT on Total AUM.

Sheet 2. Reverse Engineering
A1: REVERSE ENGINEERING YAHOO FINANCE ESTIMATES
A2: Goal: Deduce the required Loan Book Growth to hit Analyst NII Estimates
B3: FY26 (Actual) | C3: FY27 (Target) | D3: FY28 (Target)
A4: 1. Top-Line Target (NII ₹ Cr) | B4: 682.33 | C4: 882 | D4: 1007
A5: 2. NII YoY Growth | C5: 29.2% (vs FY25) | D5: 14.17%
A7: THE REVERSE SOLVER LOGIC (How we got the growth rates)
A8: NII is an output: NII = (Loan Yield * Avg Loans) - (Cost of Debt * Avg Borrowings).
A9: By holding Yield (11.85%) and Cost of Debt (8.84%) constant, we back-calculated the required loan base.
C10: Implied Loan Growth | D10: Implied Loan Book (₹ Cr)
A11: To hit ₹882 Cr NII in FY27: | B11: Requires -> | C11: 0.1399 | D11: 18320
A12: To hit ₹1,007 Cr NII in FY28: | B12: Requires -> | C12: 0.1549 | D12: 21157
A14: CONCLUSION FOR PANEL:
A15: The analyst estimates are banking on Repco accelerating its loan growth from ~12.3% (FY26) to ~15.5% (FY28).
A16: Given Repco's low D/E ratio of 3.02x, they have ample room to borrow and fund this growth.

Sheet 3. Financial Projections
A1: REPCO HOME FINANCE - INTEGRATED P&L AND BALANCE SHEET (₹ Crores)
A2: Note: Formulas are embedded. Change assumptions in yellow cells to see real-time flow.
A4: PARTICULARS | B4: FY25 (Act) | C4: FY26 (Act) | D4: FY27 (Proj) | E4: FY28 (Proj)
A5: INCOME STATEMENT
A6: Net Interest Income (NII) | B6: 682.33 | C6: 814 | D6: 882 | E6: 1007
A7: PAT Margin % | B7: 0.644 | C7: 0.644 | D7: 0.644 | E7: 0.644
A8: Profit After Tax (PAT) | B8: =B6*B7 -> 439.42052 | C8: =C6*C7 -> 524.216 | D8: =D6*D7 -> 568.008 | E8: =E6*E7 -> 648.508
A9: Dividend Payout Ratio | B9: 0.1 | C9: 0.1 | D9: 0.1 | E9: 0.1
A10: Dividends Paid | B10: =B8*B9 -> 43.942052 | C10: =C8*C9 -> 52.4216 | D10: =D8*D9 -> 56.8008 | E10: =E8*E9 -> 64.8508
A11: Retained Earnings (Added to Equity) | B11: =B8-B10 -> 395.47847 | C11: =C8-C10 -> 471.7944 | D11: =D8-D10 -> 511.2072 | E11: =E8-E10 -> 583.6572
A13: BALANCE SHEET
A14: LIABILITIES & EQUITY
A15: Total Equity (Book Value) | B15: 3427 | C15: 4041 | D15: =C15+D11 -> 4552.2072 | E15: =D15+E11 -> 5135.8644
A16: Other Liabilities (Assumed flat) | B16: 150 | C16: 198 | D16: 198 | E16: 198
A17: Borrowings (Debt) - THE PLUG | B17: 11139 | C17: 12206 | D17: =D21-D15-D16 -> 13570.266 | E17: =E21-E15-E16 -> 15824.45
A18: TOTAL LIABILITIES | B18: =SUM(B15:B17) -> 14716 | C18: =SUM(C15:C17) -> 16445 | D18: =SUM(D15:D17) -> 18320.473 | E18: =SUM(E15:E17) -> 21158.314
A20: ASSETS
A21: Loan Book / Other Assets | B21: 14310 | C21: 16072 | D21: =C21*(1+D23) -> 18320.473 | E21: =D21*(1+E23) -> 21158.314
A22: TOTAL ASSETS | B22: =B21 -> 14310 | C22: =C21 -> 16072 | D22: =D21 -> 18320.473 | E22: =E21 -> 21158.314
A23: Loan Growth Assumption | B23: 0.0589 | C23: 0.1231 | D23: 0.1399 | E23: 0.1549
A24: Balance Check (Assets - Liabs) | B24: =B22-B18 -> -406 | C24: =C22-C18 -> -373 | D24: =D22-D18 -> 0 | E24: =E22-E18 -> 0
A26: Return on Equity (ROE) = PAT / Beginning-of-Year Book Value | C26: =C8/B15 -> 0.15296644 | D26: =D8/C15 -> 0.14056125 | E26: =E8/D15 -> 0.14246012
A27: Book Value Roll-Forward Formula: Ending Equity (row 15) = Beginning Equity + Retained Earnings (row 11) = Beginning Equity + PAT - Dividends Paid.

Sheet 4. Residual Income Valuation
A1: RESIDUAL INCOME (EXCESS RETURN) VALUATION
A2: 1. COST OF EQUITY (CAPM) CALCULATION | B2: Assumption / Input | C2: Source
A3: Risk-Free Rate (Rf) | B3: 0.0678 | C3: 10Y GOI Bond Yield (Aug 2026)
A4: Beta (Levered) | B4: 0.85 | C4: Market Data / Defensive HFC
A5: Equity Risk Premium (ERP) | B5: 0.055 | C5: Damodaran India Estimate
A6: Cost of Equity (Ke) | B6: =B3+(B4*B5) -> 0.11455 | C6: Rf + Beta * ERP
A8: 2. RESIDUAL INCOME CALCULATION (₹ Crores) | B8: FY26 | C8: FY27 | D8: FY28 | E8: FY29 (Terminal Base)
A9: Starting Book Value (Total Equity) | B9: 4041 | C9: ='3. Financial Projections'!C15 -> 4041 | D9: ='3. Financial Projections'!D15 -> 4552.2072 | E9: ='3. Financial Projections'!E15 -> 5135.8644
A10: Projected PAT | C10: ='3. Financial Projections'!D8 -> 568.008 | D10: ='3. Financial Projections'!E8 -> 648.508 | E10: =D10*(1+0.1417) -> 740.40158
A11: Equity Charge (Hurdle) = BV * Ke | C11: =C9*$B$6 -> 462.89655 | D11: =D9*$B$6 -> 521.45533 | E11: =E9*$B$6 -> 588.31327
A12: Residual Income (Excess Return) = PAT - Charge | C12: =C10-C11 -> 105.11145 | D12: =D10-D11 -> 127.05267 | E12: =E10-E11 -> 152.08832
A13: Discount Factor (1+Ke)^t | C13: =(1+$B$6)^1 -> 1.11455 | D13: =(1+$B$6)^2 -> 1.2422217
A14: Present Value of Residual Income | C14: =C12/C13 -> 94.30842 | D14: =D12/D13 -> 102.27857
A16: 3. TERMINAL VALUE (Gordon Growth Model)
A17: Terminal Growth Rate (g) | B17: 0.05 | C17: Modest perpetual growth
A18: Terminal Value of RI = RI_FY29 / (Ke - g) | B18: =E12/($B$6-B17) -> 2356.1319
A19: Present Value of Terminal Value | B19: =B18/D13 -> 1896.7081 | C19: Discounted back 2 years
A21: 4. INTRINSIC VALUE PER SHARE
A22: Sum of PV of Residual Incomes (FY27-FY28) | B22: =SUM(C14:D14) -> 196.587
A23: Present Value of Terminal Value | B23: =B19 -> 1896.7081
A24: Total PV of Value Created (Excess) | B24: =B22+B23 -> 2093.2951
A25: Add: Starting Book Value (FY26 Anchor) | B25: =B9 -> 4041 | C25: Current accounting net worth
A26: Total Intrinsic Equity Value | B26: =B24+B25 -> 6134.2951
A27: Total Outstanding Shares (Crores) | B27: 6.256
A28: INTRINSIC VALUE PER SHARE (₹) | B28: =B26/B27 -> 980.54589
A29: Current Market Price (CMP) | B29: 362
A30: UPSIDE / (DOWNSIDE) | B30: =(B28-B29)/B29 -> 1.7086903
A32: 5. VALUE CREATION ANALYSIS (ROE vs Cost of Equity)
B33: FY27 | C33: FY28
A34: Return on Equity (ROE) = PAT / Beginning Book Value | B34: =C10/C9 -> 0.14056125 | C34: =D10/D9 -> 0.14246012
A35: Cost of Equity (Ke) | B35: =$B$6 -> 0.11455 | C35: =$B$6 -> 0.11455
A36: Value Spread (ROE - Ke) | B36: =B34-B35 -> 0.026011247 | C36: =C34-C35 -> 0.027910124
A37: Residual Income (₹ Cr) | B37: =C12 -> 105.11145 | C37: =D12 -> 127.05267
A38: Interpretation: Positive spread confirms ROE exceeds shareholders' required return, i.e. the company is creating economic value, not just accounting profit.
A40: 6. TERMINAL GROWTH RATE - SUSTAINABILITY CHECK (Why g = 5.0%)
A41: Retention Ratio (1 - Dividend Payout Ratio, FY28E) | B41: =1-'3. Financial Projections'!E9 -> 0.9
A42: FY28E Return on Equity (ROE) | B42: =C34 -> 0.14246012
A43: Sustainable Growth Rate = Retention Ratio x ROE | B43: =B41*B42 -> 0.12821411
A44: Terminal Growth Rate Assumption Used (g) | B44: =B17 -> 0.05
A45: Cross-Check vs Assumption | B45: =IF(B44<=B43,"Conservative (g <= Sustainable Rate)","AGGRESSIVE - Review g") -> Conservative (g <= Sustainable Rate)
...

Sheet 5.Sensitivity analysis
D4: TWO-VARIABLE SENSITIVITY: INTRINSIC VALUE PER SHARE (Rs.) vs Ke AND TERMINAL GROWTH (g)
D5: Terminal Growth/Ke | E5: =0.09 -> 0.09 | F5: 0.1 | G5: ='4. Residual Income Valuation'!B6 -> 0.11455 | H5: =0.12 -> 0.12 | I5: =0.13 -> 0.13
D6: 0.03 | E6: =((('4. Residual Income Valuation'!$C$10-'4. Residual Income Valuation'!$C$9*E$5)/(1+E$5))+(('4. Residual Income Valuation'!$D$10-'4. Residual Income Valuation'!$D$9*E$5)/(1+E$5)^2)+((('4. Residual Income Valuation'!$E$10-'4. Residual Income Valuation'!$E$9*E$5)/(E$5-$D6))/(1+E$5)^2)+'4. Residual Income Valuation'!$B$9)/'4. Residual Income Valuation'!$B$27 -> 1331.7888 | F6: =((('4. Residual Income Valuation'!$C$10-'4. Residual Income Valuation'!$C$9*F$5)/(1+F$5))+(('4. Residual Income Valuation'!$D$10-'4. Residual Income Valuation'!$D$9*F$5)/(1+F$5)^2)+((('4. Residual Income Valuation'!$E$10-'4. Residual Income Valuation'!$E$9*F$5)/(F$5-$D6))/(1+F$5)^2)+'4. Residual Income Valuation'!$B$9)/'4. Residual Income Valuation'!$B$27 -> 1123.3398 | G6: =((('4. Residual Income Valuation'!$C$10-'4. Residual Income Valuation'!$C$9*G$5)/(1+G$5))+(('4. Residual Income Valuation'!$D$10-'4. Residual Income Valuation'!$D$9*G$5)/(1+G$5)^2)+((('4. Residual Income Valuation'!$E$10-'4. Residual Income Valuation'!$E$9*G$5)/(G$5-$D6))/(1+G$5)^2)+'4. Residual Income Valuation'!$B$9)/'4. Residual Income Valuation'!$B$27 -> 908.82921 | H6: =((('4. Residual Income Valuation'!$C$10-'4. Residual Income Valuation'!$C$9*H$5)/(1+H$5))+(('4. Residual Income Valuation'!$D$10-'4. Residual Income Valuation'!$D$9*H$5)/(1+H$5)^2)+((('4. Residual Income Valuation'!$E$10-'4. Residual Income Valuation'!$E$9*H$5)/(H$5-$D6))/(1+H$5)^2)+'4. Residual Income Valuation'!$B$9)/'4. Residual Income Valuation'!$B$27 -> 846.5339 | I6: =((('4. Residual Income Valuation'!$C$10-'4. Residual Income Valuation'!$C$9*I$5)/(1+I$5))+(('4. Residual Income Valuation'!$D$10-'4. Residual Income Valuation'!$D$9*I$5)/(1+I$5)^2)+((('4. Residual Income Valuation'!$E$10-'4. Residual Income Valuation'!$E$9*I$5)/(I$5-$D6))/(1+I$5)^2)+'4. Residual Income Valuation'!$B$9)/'4. Residual Income Valuation'!$B$27 -> 750.13487
D7: 0.04 | E7: =((('4. Residual Income Valuation'!$C$10-'4. Residual Income Valuation'!$C$9*E$5)/(1+E$5))+(('4. Residual Income Valuation'!$D$10-'4. Residual Income Valuation'!$D$9*E$5)/(1+E$5)^2)+((('4. Residual Income Valuation'!$E$10-'4. Residual Income Valuation'!$E$9*E$5)/(E$5-$D7))/(1+E$5)^2)+'4. Residual Income Valuation'!$B$9)/'4. Residual Income Valuation'!$B$27 -> 1456.5401 | F7: =((('4. Residual Income Valuation'!$C$10-'4. Residual Income Valuation'!$C$9*F$5)/(1+F$5))+(('4. Residual Income Valuation'!$D$10-'4. Residual Income Valuation'!$D$9*F$5)/(1+F$5)^2)+((('4. Residual Income Valuation'!$E$10-'4. Residual Income Valuation'!$E$9*F$5)/(F$5-$D7))/(1+F$5)^2)+'4. Residual Income Valuation'!$B$9)/'4. Residual Income Valuation'!$B$27 -> 1194.681 | G7: =((('4. Residual Income Valuation'!$C$10-'4. Residual Income Valuation'!$C$9*G$5)/(1+G$5))+(('4. Residual Income Valuation'!$D$10-'4. Residual Income Valuation'!$D$9*G$5)/(1+G$5)^2)+((('4. Residual Income Valuation'!$E$10-'4. Residual Income Valuation'!$E$9*G$5)/(G$5-$D7))/(1+G$5)^2)+'4. Residual Income Valuation'!$B$9)/'4. Residual Income Valuation'!$B$27 -> 939.87758 | H7: =((('4. Residual Income Valuation'!$C$10-'4. Residual Income Valuation'!$C$9*H$5)/(1+H$5))+(('4. Residual Income Valuation'!$D$10-'4. Residual Income Valuation'!$D$9*H$5)/(1+H$5)^2)+((('4. Residual Income Valuation'!$E$10-'4. Residual Income Valuation'!$E$9*H$5)/(H$5-$D7))/(1+H$5)^2)+'4. Residual Income Valuation'!$B$9)/'4. Residual Income Valuation'!$B$27 -> 868.49727 | I7: =((('4. Residual Income Valuation'!$C$10-'4. Residual Income Valuation'!$C$9*I$5)/(1+I$5))+(('4. Residual Income Valuation'!$D$10-'4. Residual Income Valuation'!$D$9*I$5)/(1+I$5)^2)+((('4. Residual Income Valuation'!$E$10-'4. Residual Income Valuation'!$E$9*I$5)/(I$5-$D7))/(1+I$5)^2)+'4. Residual Income Valuation'!$B$9)/'4. Residual Income Valuation'!$B$27 -> 760.25236
D8: ='4. Residual Income Valuation'!B17 -> 0.05 | E8: =((('4. Residual Income Valuation'!$C$10-'4. Residual Income Valuation'!$C$9*E$5)/(1+E$5))+(('4. Residual Income Valuation'!$D$10-'4. Residual Income Valuation'!$D$9*E$5)/(1+E$5)^2)+((('4. Residual Income Valuation'!$E$10-'4. Residual Income Valuation'!$E$9*E$5)/(E$5-$D8))/(1+E$5)^2)+'4. Residual Income Valuation'!$B$9)/'4. Residual Income Valuation'!$B$27 -> 1643.6671 | F8: =((('4. Residual Income Valuation'!$C$10-'4. Residual Income Valuation'!$C$9*F$5)/(1+F$5))+(('4. Residual Income Valuation'!$D$10-'4. Residual Income Valuation'!$D$9*F$5)/(1+F$5)^2)+((('4. Residual Income Valuation'!$E$10-'4. Residual Income Valuation'!$E$9*F$5)/(F$5-$D8))/(1+F$5)^2)+'4. Residual Income Valuation'!$B$9)/'4. Residual Income Valuation'!$B$27 -> 1294.5587 | G8: =((('4. Residual Income Valuation'!$C$10-'4. Residual Income Valuation'!$C$9*G$5)/(1+G$5))+(('4. Residual Income Valuation'!$D$10-'4. Residual Income Valuation'!$D$9*G$5)/(1+G$5)^2)+((('4. Residual Income Valuation'!$E$10-'4. Residual Income Valuation'!$E$9*G$5)/(G$5-$D8))/(1+G$5)^2)+'4. Residual Income Valuation'!$B$9)/'4. Residual Income Valuation'!$B$27 -> 980.54589 | H8: =((('4. Residual Income Valuation'!$C$10-'4. Residual Income Valuation'!$C$9*H$5)/(1+H$5))+(('4. Residual Income Valuation'!$D$10-'4. Residual Income Valuation'!$D$9*H$5)/(1+H$5)^2)+((('4. Residual Income Valuation'!$E$10-'4. Residual Income Valuation'!$E$9*H$5)/(H$5-$D8))/(1+H$5)^2)+'4. Residual Income Valuation'!$B$9)/'4. Residual Income Valuation'!$B$27 -> 896.73589 | I8: =((('4. Residual Income Valuation'!$C$10-'4. Residual Income Valuation'!$C$9*I$5)/(1+I$5))+(('4. Residual Income Valuation'!$D$10-'4. Residual Income Valuation'!$D$9*I$5)/(1+I$5)^2)+((('4. Residual Income Valuation'!$E$10-'4. Residual Income Valuation'!$E$9*I$5)/(I$5-$D8))/(1+I$5)^2)+'4. Residual Income Valuation'!$B$9)/'4. Residual Income Valuation'!$B$27 -> 772.89921
D9: 0.06 | E9: =((('4. Residual Income Valuation'!$C$10-'4. Residual Income Valuation'!$C$9*E$5)/(1+E$5))+(('4. Residual Income Valuation'!$D$10-'4. Residual Income Valuation'!$D$9*E$5)/(1+E$5)^2)+((('4. Residual Income Valuation'!$E$10-'4. Residual Income Valuation'!$E$9*E$5)/(E$5-$D9))/(1+E$5)^2)+'4. Residual Income Valuation'!$B$9)/'4. Residual Income Valuation'!$B$27 -> 1955.5455 | F9: =((('4. Residual Income Valuation'!$C$10-'4. Residual Income Valuation'!$C$9*F$5)/(1+F$5))+(('4. Residual Income Valuation'!$D$10-'4. Residual Income Valuation'!$D$9*F$5)/(1+F$5)^2)+((('4. Residual Income Valuation'!$E$10-'4. Residual Income Valuation'!$E$9*F$5)/(F$5-$D9))/(1+F$5)^2)+'4. Residual Income Valuation'!$B$9)/'4. Residual Income Valuation'!$B$27 -> 1444.3753 | G9: =((('4. Residual Income Valuation'!$C$10-'4. Residual Income Valuation'!$C$9*G$5)/(1+G$5))+(('4. Residual Income Valuation'!$D$10-'4. Residual Income Valuation'!$D$9*G$5)/(1+G$5)^2)+((('4. Residual Income Valuation'!$E$10-'4. Residual Income Valuation'!$E$9*G$5)/(G$5-$D9))/(1+G$5)^2)+'4. Residual Income Valuation'!$B$9)/'4. Residual Income Valuation'!$B$27 -> 1036.1247 | H9: =((('4. Residual Income Valuation'!$C$10-'4. Residual Income Valuation'!$C$9*H$5)/(1+H$5))+(('4. Residual Income Valuation'!$D$10-'4. Residual Income Valuation'!$D$9*H$5)/(1+H$5)^2)+((('4. Residual Income Valuation'!$E$10-'4. Residual Income Valuation'!$E$9*H$5)/(H$5-$D9))/(1+H$5)^2)+'4. Residual Income Valuation'!$B$9)/'4. Residual Income Valuation'!$B$27 -> 934.38739 | I9: =((('4. Residual Income Valuation'!$C$10-'4. Residual Income Valuation'!$C$9*I$5)/(1+I$5))+(('4. Residual Income Valuation'!$D$10-'4. Residual Income Valuation'!$D$9*I$5)/(1+I$5)^2)+((('4. Residual Income Valuation'!$E$10-'4. Residual Income Valuation'!$E$9*I$5)/(I$5-$D9))/(1+I$5)^2)+'4. Residual Income Valuation'!$B$9)/'4. Residual Income Valuation'!$B$27 -> 789.15945
D10: 0.07 | E10: =((('4. Residual Income Valuation'!$C$10-'4. Residual Income Valuation'!$C$9*E$5)/(1+E$5))+(('4. Residual Income Valuation'!$D$10-'4. Residual Income Valuation'!$D$9*E$5)/(1+E$5)^2)+((('4. Residual Income Valuation'!$E$10-'4. Residual Income Valuation'!$E$9*E$5)/(E$5-$D10))/(1+E$5)^2)+'4. Residual Income Valuation'!$B$9)/'4. Residual Income Valuation'!$B$27 -> 2579.3022 | F10: =((('4. Residual Income Valuation'!$C$10-'4. Residual Income Valuation'!$C$9*F$5)/(1+F$5))+(('4. Residual Income Valuation'!$D$10-'4. Residual Income Valuation'!$D$9*F$5)/(1+F$5)^2)+((('4. Residual Income Valuation'!$E$10-'4. Residual Income Valuation'!$E$9*F$5)/(F$5-$D10))/(1+F$5)^2)+'4. Residual Income Valuation'!$B$9)/'4. Residual Income Valuation'!$B$27 -> 1694.0697 | G10: =((('4. Residual Income Valuation'!$C$10-'4. Residual Income Valuation'!$C$9*G$5)/(1+G$5))+(('4. Residual Income Valuation'!$D$10-'4. Residual Income Valuation'!$D$9*G$5)/(1+G$5)^2)+((('4. Residual Income Valuation'!$E$10-'4. Residual Income Valuation'!$E$9*G$5)/(G$5-$D10))/(1+G$5)^2)+'4. Residual Income Valuation'!$B$9)/'4. Residual Income Valuation'!$B$27 -> 1116.6546 | H10: =((('4. Residual Income Valuation'!$C$10-'4. Residual Income Valuation'!$C$9*H$5)/(1+H$5))+(('4. Residual Income Valuation'!$D$10-'4. Residual Income Valuation'!$D$9*H$5)/(1+H$5)^2)+((('4. Residual Income Valuation'!$E$10-'4. Residual Income Valuation'!$E$9*H$5)/(H$5-$D10))/(1+H$5)^2)+'4. Residual Income Valuation'!$B$9)/'4. Residual Income Valuation'!$B$27 -> 987.09948 | I10: =((('4. Residual Income Valuation'!$C$10-'4. Residual Income Valuation'!$C$9*I$5)/(1+I$5))+(('4. Residual Income Valuation'!$D$10-'4. Residual Income Valuation'!$D$9*I$5)/(1+I$5)^2)+((('4. Residual Income Valuation'!$E$10-'4. Residual Income Valuation'!$E$9*I$5)/(I$5-$D10))/(1+I$5)^2)+'4. Residual Income Valuation'!$B$9)/'4. Residual Income Valuation'!$B$27 -> 810.83977
D12: SCENARIO SUMMARY: BEAR / BASE / BULL CASE
D13: Scenario | E13: Cost of Equity (Ke) | F13: Terminal Growth (g) | G13: Intrinsic Value/Share (Rs.) | H13: Upside/(Downside) vs CMP
D14: Bear Case | E14: =I5 -> 0.13 | F14: =D6 -> 0.03 | G14: =I6 -> 750.13487 | H14: =(G14-'4. Residual Income Valuation'!$B$29)/'4. Residual Income Valuation'!$B$29 -> 1.0721958
D15: Base Case | E15: =G5 -> 0.11455 | F15: =D8 -> 0.05 | G15: =G8 -> 980.54589 | H15: =(G15-'4. Residual Income Valuation'!$B$29)/'4. Residual Income Valuation'!$B$29 -> 1.7086903
D16: Bull Case | E16: =E5 -> 0.09 | F16: =D10 -> 0.07 | G16: =E10 -> 2579.3022 | H16: =(G16-'4. Residual Income Valuation'!$B$29)/'4. Residual Income Valuation'!$B$29 -> 6.1251441
D18: 7. INVESTMENT CONCLUSION (Auto-Generated from Model)
D19: ="Across a Ke range of 9%-13% and terminal growth range of 3%-7%, estimated intrinsic value ranges from Rs."&TEXT(I6,"#,##0")&" (Bear Case) to Rs."&TEXT(E10,"#,##0")&" (Bull Case) per share, versus a CMP of Rs."&TEXT('4. Residual Income Valuation'!$B$29,"#,##0")&". The Base Case of Rs."&TEXT(G8,"#,##0")&" implies "&TEXT((G8-'4. Residual Income Valuation'!$B$29)/'4. Residual Income Valuation'!$B$29,"0.0%")&" upside. The stock screens as undervalued in every scenario tested, but the Base Case figure should be read as a scenario estimate, not a precise price target." -> Across a Ke range of 9%-13% and terminal growth range of 3%-7%, estimated intrinsic value ranges from Rs.750 (Bear Case) to Rs.2,579 (Bull Case) per share, versus a CMP of Rs.362. The Base Case of Rs.981 implies 170.9% upside. The stock screens as undervalued in every scenario tested, but the Base Case figure should be read as a scenario estimate, not a precise price target.
D24: Reading the grid: Base Case (green cell) uses the CAPM-derived Ke of 11.46% and the 5.0% terminal growth assumption justified on Sheet 4. Move along a row to test Ke sensitivity at a fixed growth rate; move down a column to test growth sensitivity at a fixed Ke. Every cell recalculates live off the same underlying PAT and Book Value projections - only Ke and g change.

Sheet 6. Methodology Guide
A1: HOW THIS MODEL WORKS - STEP-BY-STEP FORMULA GUIDE
A2: Use this sheet as a reusable template for building a Residual Income (Excess Return) valuation for any bank, NBFC, or HFC.
A4: # | B4: Sheet | C4: Line Item | D4: Excel Formula (as used in this model) | E4: Why It Matters
A5: 1 | B5: Sheet 2 | C5: Reverse-engineer growth | D5: Formula: solve loan growth so that (yield x avg loans) - (cost of debt x avg borrowings) = target nii | E5: Never accept an analyst NII/EPS estimate at face value - back it into an implied balance-sheet growth rate and sanity-check it.
A6: 2 | B6: Sheet 3 | C6: PAT | D6: Formula: nii x pat margin % | E6: Keeps the P&L driven by two clearly stated assumptions instead of a hardcoded profit number.
A7: 3 | B7: Sheet 3 | C7: Retained Earnings | D7: Formula: pat - dividends paid, where dividends = pat x payout ratio | E7: Explicitly separates the portion of profit that re-capitalises the business from the portion paid out.
A8: 4 | B8: Sheet 3 | C8: Ending Book Value (roll-forward) | D8: Formula: beginning book value + retained earnings | E8: This is the single most-asked question in a valuation defence - always be able to show the BV bridge.
A9: 5 | B9: Sheet 3 | C9: Borrowings ("the plug") | D9: Formula: total assets - equity - other liabilities | E9: For a lender, debt is a balancing item, not an assumption - hardcoding a D/E ratio double-counts growth.
A10: 6 | B10: Sheet 3 | C10: Return on Equity (ROE) | D10: Formula: pat / beginning-of-year book value | E10: ROE, not PAT growth, is what determines whether a lender is creating or destroying shareholder value.
A11: 7 | B11: Sheet 4 | C11: Cost of Equity (Ke) - CAPM | D11: Formula: risk-free rate + beta x equity risk premium | E11: Standard CAPM. Source each input (G-Sec yield, sector beta, Damodaran ERP) - never guess Ke.
A12: 8 | B12: Sheet 4 | C12: Equity Charge (hurdle) | D12: Formula: beginning book value x ke | E12: The minimum profit shareholders require for the capital tied up in the business - the benchmark PAT must clear.
A13: 9 | B13: Sheet 4 | C13: Residual Income (Excess Return) | D13: Formula: projected pat - equity charge | E13: Positive RI = value creation. This is the core insight the whole model is built to test.
A14: 10 | B14: Sheet 4 | C14: PV of Residual Income | D14: Formula: residual income / (1+ke)^t | E14: Discounts each year of excess return back to today at the cost of equity.
A15: 11 | B15: Sheet 4 | C15: Terminal Value of RI (Gordon Growth) | D15: Formula: ri in terminal year / (ke - g) | E15: Capitalises all excess returns beyond the explicit forecast into a single perpetuity value.
A16: 12 | B16: Sheet 4 | C16: PV of Terminal Value | D16: Formula: terminal value / (1+ke)^n | E16: Brings the terminal value back to present-day rupees using the same discount factor as the final forecast year.
... A22: 18 | B22: Sheet 5 | C22: Bear / Base / Bull scenarios | D22: Pulled directly from the corners and centre of the sensitivity grid | E22: Converts a spreadsheet of numbers into three headline scenarios a non-technical panel member can follow.
A24: GOLDEN RULES FOR BUILDING YOUR OWN MODEL
A25: - Never hardcode a result - every calculated cell should be a formula that recalculates if an assumption changes.
A26: - Color-code every hardcoded input in blue font on yellow fill; leave every formula in plain black - a reviewer should know in one glance what is an assumption vs. a calculation.
A27: - For lenders (banks/NBFCs/HFCs), value equity with Residual Income or Excess Return, not FCFE - loan growth consumes cash, which makes FCFE misleadingly negative.
A28: - Always tie your Balance Sheet out explicitly (Assets = Liabilities + Equity) with a visible "Balance Check" row that must equal zero.
A29: - Test ROE vs. Cost of Equity, not just absolute profit growth - a growing but sub-Ke ROE business destroys value even while PAT rises.
A30: - Never present a single-point valuation - always show a Ke x g sensitivity grid and a Bear/Base/Bull range before drawing a conclusion.
A31: - Justify your terminal growth rate with a Sustainable Growth cross-check (Retention Ratio x ROE) and a reference to long-run GDP growth - never pick g by feel.
A32: - State your final conclusion as a range and a probability-weighted view ("undervalued under base-case assumptions"), not a single confident number.
